[2023-05-07T22:59:23.838+0000] {taskinstance.py:1125} INFO - Dependencies all met for dep_context=non-requeueable deps ti=<TaskInstance: Summer_Warped_ETL.LoadData.Load manual__2023-05-07T22:54:30.361863+00:00 [queued]>
[2023-05-07T22:59:23.844+0000] {taskinstance.py:1125} INFO - Dependencies all met for dep_context=requeueable deps ti=<TaskInstance: Summer_Warped_ETL.LoadData.Load manual__2023-05-07T22:54:30.361863+00:00 [queued]>
[2023-05-07T22:59:23.844+0000] {taskinstance.py:1331} INFO - Starting attempt 4 of 5
[2023-05-07T22:59:23.851+0000] {taskinstance.py:1350} INFO - Executing <Task(PythonOperator): LoadData.Load> on 2023-05-07 22:54:30.361863+00:00
[2023-05-07T22:59:23.855+0000] {standard_task_runner.py:57} INFO - Started process 598 to run task
[2023-05-07T22:59:23.859+0000] {standard_task_runner.py:84} INFO - Running: ['***', 'tasks', 'run', 'Summer_Warped_ETL', 'LoadData.Load', 'manual__2023-05-07T22:54:30.361863+00:00', '--job-id', '1568', '--raw', '--subdir', 'DAGS_FOLDER/warped-dag.py', '--cfg-path', '/tmp/tmp1r_zv6ju']
[2023-05-07T22:59:23.859+0000] {standard_task_runner.py:85} INFO - Job 1568: Subtask LoadData.Load
[2023-05-07T22:59:23.896+0000] {task_command.py:410} INFO - Running <TaskInstance: Summer_Warped_ETL.LoadData.Load manual__2023-05-07T22:54:30.361863+00:00 [running]> on host fa349db4fc2f
[2023-05-07T22:59:23.951+0000] {taskinstance.py:1570} INFO - Exporting env vars: AIRFLOW_CTX_DAG_OWNER='Ananta Moharana' AIRFLOW_CTX_DAG_ID='Summer_Warped_ETL' AIRFLOW_CTX_TASK_ID='LoadData.Load' AIRFLOW_CTX_EXECUTION_DATE='2023-05-07T22:54:30.361863+00:00' AIRFLOW_CTX_TRY_NUMBER='4' AIRFLOW_CTX_DAG_RUN_ID='manual__2023-05-07T22:54:30.361863+00:00'
[2023-05-07T22:59:23.952+0000] {logging_mixin.py:149} INFO - 2023-05/song_dim.csv
[2023-05-07T22:59:23.959+0000] {base.py:73} INFO - Using connection ID 'aws_connection' for task execution.
[2023-05-07T22:59:23.960+0000] {connection_wrapper.py:337} INFO - AWS Connection (conn_id='aws_connection', conn_type='aws') credentials retrieved from login and password.
[2023-05-07T22:59:24.242+0000] {logging_mixin.py:149} INFO -        song_name                 song_id  explicit  ...    tempo  valence  mode
0          WINGZ  7evQqGTWfKz8hIHzLVzneT     False  ...  170.025    0.120     0
1  lights (4444)  3PDNGdhCtiQemL14eKhCup      True  ...   89.982    0.428     1
2         softie  1bLEa8W1VVMFBIwp9hKYTL      True  ...  119.063    0.498     0
3    do me wrong  7H74AdiJYM7hh4SYGrq9xe     False  ...  174.960    0.396     0
4            HMU  2SWK4LJWLyev4yVYIVhjEV     False  ...   72.993    0.389     1

[5 rows x 15 columns]
[2023-05-07T22:59:24.242+0000] {logging_mixin.py:149} INFO - ['song_name', 'song_id', 'explicit', 'acousticness', 'danceability', 'duration_ms', 'energy', 'instrumentalness', 'key', 'liveness', 'loudness', 'speechiness', 'tempo', 'valence', 'mode']
[2023-05-07T22:59:24.249+0000] {base.py:73} INFO - Using connection ID '***' for task execution.
[2023-05-07T22:59:34.265+0000] {taskinstance.py:1847} ERROR - Task failed with exception
Traceback (most recent call last):
  File "/home/airflow/.local/lib/python3.7/site-packages/sqlalchemy/engine/base.py", line 3361, in _wrap_pool_connect
    return fn()
  File "/home/airflow/.local/lib/python3.7/site-packages/sqlalchemy/pool/base.py", line 327, in connect
    return _ConnectionFairy._checkout(self)
  File "/home/airflow/.local/lib/python3.7/site-packages/sqlalchemy/pool/base.py", line 894, in _checkout
    fairy = _ConnectionRecord.checkout(pool)
  File "/home/airflow/.local/lib/python3.7/site-packages/sqlalchemy/pool/base.py", line 493, in checkout
    rec = pool._do_get()
  File "/home/airflow/.local/lib/python3.7/site-packages/sqlalchemy/pool/impl.py", line 146, in _do_get
    self._dec_overflow()
  File "/home/airflow/.local/lib/python3.7/site-packages/sqlalchemy/util/langhelpers.py", line 72, in __exit__
    with_traceback=exc_tb,
  File "/home/airflow/.local/lib/python3.7/site-packages/sqlalchemy/util/compat.py", line 211, in raise_
    raise exception
  File "/home/airflow/.local/lib/python3.7/site-packages/sqlalchemy/pool/impl.py", line 143, in _do_get
    return self._create_connection()
  File "/home/airflow/.local/lib/python3.7/site-packages/sqlalchemy/pool/base.py", line 273, in _create_connection
    return _ConnectionRecord(self)
  File "/home/airflow/.local/lib/python3.7/site-packages/sqlalchemy/pool/base.py", line 388, in __init__
    self.__connect()
  File "/home/airflow/.local/lib/python3.7/site-packages/sqlalchemy/pool/base.py", line 691, in __connect
    pool.logger.debug("Error on connect(): %s", e)
  File "/home/airflow/.local/lib/python3.7/site-packages/sqlalchemy/util/langhelpers.py", line 72, in __exit__
    with_traceback=exc_tb,
  File "/home/airflow/.local/lib/python3.7/site-packages/sqlalchemy/util/compat.py", line 211, in raise_
    raise exception
  File "/home/airflow/.local/lib/python3.7/site-packages/sqlalchemy/pool/base.py", line 686, in __connect
    self.dbapi_connection = connection = pool._invoke_creator(self)
  File "/home/airflow/.local/lib/python3.7/site-packages/sqlalchemy/engine/create.py", line 574, in connect
    return dialect.connect(*cargs, **cparams)
  File "/home/airflow/.local/lib/python3.7/site-packages/sqlalchemy/engine/default.py", line 598, in connect
    return self.dbapi.connect(*cargs, **cparams)
  File "/home/airflow/.local/lib/python3.7/site-packages/psycopg2/__init__.py", line 122, in connect
    conn = _connect(dsn, connection_factory=connection_factory, **kwasync)
psycopg2.OperationalError: could not translate host name "host.docker.local" to address: Temporary failure in name resolution


The above exception was the direct cause of the following exception:

Traceback (most recent call last):
  File "/home/airflow/.local/lib/python3.7/site-packages/airflow/operators/python.py", line 181, in execute
    return_value = self.execute_callable()
  File "/home/airflow/.local/lib/python3.7/site-packages/airflow/operators/python.py", line 198, in execute_callable
    return self.python_callable(*self.op_args, **self.op_kwargs)
  File "/opt/airflow/dags/src/load.py", line 35, in upload_to_database
    df.to_sql(name=table, con=postgres_hook.get_sqlalchemy_engine(), if_exists='replace', index=False)
  File "/home/airflow/.local/lib/python3.7/site-packages/pandas/core/generic.py", line 2882, in to_sql
    method=method,
  File "/home/airflow/.local/lib/python3.7/site-packages/pandas/io/sql.py", line 728, in to_sql
    **engine_kwargs,
  File "/home/airflow/.local/lib/python3.7/site-packages/pandas/io/sql.py", line 1758, in to_sql
    dtype=dtype,
  File "/home/airflow/.local/lib/python3.7/site-packages/pandas/io/sql.py", line 1650, in prep_table
    table.create()
  File "/home/airflow/.local/lib/python3.7/site-packages/pandas/io/sql.py", line 856, in create
    if self.exists():
  File "/home/airflow/.local/lib/python3.7/site-packages/pandas/io/sql.py", line 840, in exists
    return self.pd_sql.has_table(self.name, self.schema)
  File "/home/airflow/.local/lib/python3.7/site-packages/pandas/io/sql.py", line 1783, in has_table
    insp = sa.inspect(self.connectable)
  File "/home/airflow/.local/lib/python3.7/site-packages/sqlalchemy/inspection.py", line 64, in inspect
    ret = reg(subject)
  File "/home/airflow/.local/lib/python3.7/site-packages/sqlalchemy/engine/reflection.py", line 182, in _engine_insp
    return Inspector._construct(Inspector._init_engine, bind)
  File "/home/airflow/.local/lib/python3.7/site-packages/sqlalchemy/engine/reflection.py", line 117, in _construct
    init(self, bind)
  File "/home/airflow/.local/lib/python3.7/site-packages/sqlalchemy/engine/reflection.py", line 128, in _init_engine
    engine.connect().close()
  File "/home/airflow/.local/lib/python3.7/site-packages/sqlalchemy/engine/base.py", line 3315, in connect
    return self._connection_cls(self, close_with_result=close_with_result)
  File "/home/airflow/.local/lib/python3.7/site-packages/sqlalchemy/engine/base.py", line 96, in __init__
    else engine.raw_connection()
  File "/home/airflow/.local/lib/python3.7/site-packages/sqlalchemy/engine/base.py", line 3394, in raw_connection
    return self._wrap_pool_connect(self.pool.connect, _connection)
  File "/home/airflow/.local/lib/python3.7/site-packages/sqlalchemy/engine/base.py", line 3365, in _wrap_pool_connect
    e, dialect, self
  File "/home/airflow/.local/lib/python3.7/site-packages/sqlalchemy/engine/base.py", line 2199, in _handle_dbapi_exception_noconnection
    sqlalchemy_exception, with_traceback=exc_info[2], from_=e
  File "/home/airflow/.local/lib/python3.7/site-packages/sqlalchemy/util/compat.py", line 211, in raise_
    raise exception
  File "/home/airflow/.local/lib/python3.7/site-packages/sqlalchemy/engine/base.py", line 3361, in _wrap_pool_connect
    return fn()
  File "/home/airflow/.local/lib/python3.7/site-packages/sqlalchemy/pool/base.py", line 327, in connect
    return _ConnectionFairy._checkout(self)
  File "/home/airflow/.local/lib/python3.7/site-packages/sqlalchemy/pool/base.py", line 894, in _checkout
    fairy = _ConnectionRecord.checkout(pool)
  File "/home/airflow/.local/lib/python3.7/site-packages/sqlalchemy/pool/base.py", line 493, in checkout
    rec = pool._do_get()
  File "/home/airflow/.local/lib/python3.7/site-packages/sqlalchemy/pool/impl.py", line 146, in _do_get
    self._dec_overflow()
  File "/home/airflow/.local/lib/python3.7/site-packages/sqlalchemy/util/langhelpers.py", line 72, in __exit__
    with_traceback=exc_tb,
  File "/home/airflow/.local/lib/python3.7/site-packages/sqlalchemy/util/compat.py", line 211, in raise_
    raise exception
  File "/home/airflow/.local/lib/python3.7/site-packages/sqlalchemy/pool/impl.py", line 143, in _do_get
    return self._create_connection()
  File "/home/airflow/.local/lib/python3.7/site-packages/sqlalchemy/pool/base.py", line 273, in _create_connection
    return _ConnectionRecord(self)
  File "/home/airflow/.local/lib/python3.7/site-packages/sqlalchemy/pool/base.py", line 388, in __init__
    self.__connect()
  File "/home/airflow/.local/lib/python3.7/site-packages/sqlalchemy/pool/base.py", line 691, in __connect
    pool.logger.debug("Error on connect(): %s", e)
  File "/home/airflow/.local/lib/python3.7/site-packages/sqlalchemy/util/langhelpers.py", line 72, in __exit__
    with_traceback=exc_tb,
  File "/home/airflow/.local/lib/python3.7/site-packages/sqlalchemy/util/compat.py", line 211, in raise_
    raise exception
  File "/home/airflow/.local/lib/python3.7/site-packages/sqlalchemy/pool/base.py", line 686, in __connect
    self.dbapi_connection = connection = pool._invoke_creator(self)
  File "/home/airflow/.local/lib/python3.7/site-packages/sqlalchemy/engine/create.py", line 574, in connect
    return dialect.connect(*cargs, **cparams)
  File "/home/airflow/.local/lib/python3.7/site-packages/sqlalchemy/engine/default.py", line 598, in connect
    return self.dbapi.connect(*cargs, **cparams)
  File "/home/airflow/.local/lib/python3.7/site-packages/psycopg2/__init__.py", line 122, in connect
    conn = _connect(dsn, connection_factory=connection_factory, **kwasync)
sqlalchemy.exc.OperationalError: (psycopg2.OperationalError) could not translate host name "host.docker.local" to address: Temporary failure in name resolution

(Background on this error at: https://sqlalche.me/e/14/e3q8)
[2023-05-07T22:59:34.283+0000] {taskinstance.py:1373} INFO - Marking task as UP_FOR_RETRY. dag_id=Summer_Warped_ETL, task_id=LoadData.Load, execution_date=20230507T225430, start_date=20230507T225923, end_date=20230507T225934
[2023-05-07T22:59:34.292+0000] {standard_task_runner.py:109} ERROR - Failed to execute job 1568 for task LoadData.Load ((psycopg2.OperationalError) could not translate host name "host.docker.local" to address: Temporary failure in name resolution

(Background on this error at: https://sqlalche.me/e/14/e3q8); 598)
[2023-05-07T22:59:34.324+0000] {local_task_job_runner.py:232} INFO - Task exited with return code 1
[2023-05-07T22:59:34.344+0000] {taskinstance.py:2674} INFO - 0 downstream tasks scheduled from follow-on schedule check
