[2023-05-09T19:16:18.017+0000] {taskinstance.py:1125} INFO - Dependencies all met for dep_context=non-requeueable deps ti=<TaskInstance: Summer_Warped_ETL.LoadData.LoadSongDim manual__2023-05-09T19:16:16.189302+00:00 [queued]>
[2023-05-09T19:16:18.026+0000] {taskinstance.py:1125} INFO - Dependencies all met for dep_context=requeueable deps ti=<TaskInstance: Summer_Warped_ETL.LoadData.LoadSongDim manual__2023-05-09T19:16:16.189302+00:00 [queued]>
[2023-05-09T19:16:18.027+0000] {taskinstance.py:1331} INFO - Starting attempt 1 of 3
[2023-05-09T19:16:18.036+0000] {taskinstance.py:1350} INFO - Executing <Task(PythonOperator): LoadData.LoadSongDim> on 2023-05-09 19:16:16.189302+00:00
[2023-05-09T19:16:18.043+0000] {standard_task_runner.py:57} INFO - Started process 322 to run task
[2023-05-09T19:16:18.047+0000] {standard_task_runner.py:84} INFO - Running: ['***', 'tasks', 'run', 'Summer_Warped_ETL', 'LoadData.LoadSongDim', 'manual__2023-05-09T19:16:16.189302+00:00', '--job-id', '2985', '--raw', '--subdir', 'DAGS_FOLDER/warped-dag.py', '--cfg-path', '/tmp/tmp8r4rh5ab']
[2023-05-09T19:16:18.047+0000] {standard_task_runner.py:85} INFO - Job 2985: Subtask LoadData.LoadSongDim
[2023-05-09T19:16:18.123+0000] {task_command.py:410} INFO - Running <TaskInstance: Summer_Warped_ETL.LoadData.LoadSongDim manual__2023-05-09T19:16:16.189302+00:00 [running]> on host 4b5a01a6ab5f
[2023-05-09T19:16:18.235+0000] {taskinstance.py:1570} INFO - Exporting env vars: AIRFLOW_CTX_DAG_OWNER='Ananta Moharana' AIRFLOW_CTX_DAG_ID='Summer_Warped_ETL' AIRFLOW_CTX_TASK_ID='LoadData.LoadSongDim' AIRFLOW_CTX_EXECUTION_DATE='2023-05-09T19:16:16.189302+00:00' AIRFLOW_CTX_TRY_NUMBER='1' AIRFLOW_CTX_DAG_RUN_ID='manual__2023-05-09T19:16:16.189302+00:00'
[2023-05-09T19:16:18.237+0000] {logging_mixin.py:149} INFO - 2023-05/song_dim.csv
[2023-05-09T19:16:18.257+0000] {base.py:73} INFO - Using connection ID 'aws_connection' for task execution.
[2023-05-09T19:16:18.258+0000] {connection_wrapper.py:337} INFO - AWS Connection (conn_id='aws_connection', conn_type='aws') credentials retrieved from login and password.
[2023-05-09T19:16:18.531+0000] {taskinstance.py:1847} ERROR - Task failed with exception
Traceback (most recent call last):
  File "/home/airflow/.local/lib/python3.7/site-packages/airflow/operators/python.py", line 181, in execute
    return_value = self.execute_callable()
  File "/home/airflow/.local/lib/python3.7/site-packages/airflow/operators/python.py", line 198, in execute_callable
    return self.python_callable(*self.op_args, **self.op_kwargs)
  File "/opt/airflow/dags/src/load.py", line 28, in upload_to_database
    df=pd.read_csv(StringIO(hook.read_key(key, s3_bucket)))
  File "/home/airflow/.local/lib/python3.7/site-packages/airflow/providers/amazon/aws/hooks/s3.py", line 111, in wrapper
    return func(*bound_args.args, **bound_args.kwargs)
  File "/home/airflow/.local/lib/python3.7/site-packages/airflow/providers/amazon/aws/hooks/s3.py", line 82, in wrapper
    return func(*bound_args.args, **bound_args.kwargs)
  File "/home/airflow/.local/lib/python3.7/site-packages/airflow/providers/amazon/aws/hooks/s3.py", line 558, in read_key
    obj = self.get_key(key, bucket_name)
  File "/home/airflow/.local/lib/python3.7/site-packages/airflow/providers/amazon/aws/hooks/s3.py", line 111, in wrapper
    return func(*bound_args.args, **bound_args.kwargs)
  File "/home/airflow/.local/lib/python3.7/site-packages/airflow/providers/amazon/aws/hooks/s3.py", line 82, in wrapper
    return func(*bound_args.args, **bound_args.kwargs)
  File "/home/airflow/.local/lib/python3.7/site-packages/airflow/providers/amazon/aws/hooks/s3.py", line 542, in get_key
    obj.load()
  File "/home/airflow/.local/lib/python3.7/site-packages/boto3/resources/factory.py", line 564, in do_action
    response = action(self, *args, **kwargs)
  File "/home/airflow/.local/lib/python3.7/site-packages/boto3/resources/action.py", line 88, in __call__
    response = getattr(parent.meta.client, operation_name)(*args, **params)
  File "/home/airflow/.local/lib/python3.7/site-packages/botocore/client.py", line 530, in _api_call
    return self._make_api_call(operation_name, kwargs)
  File "/home/airflow/.local/lib/python3.7/site-packages/botocore/client.py", line 960, in _make_api_call
    raise error_class(parsed_response, operation_name)
botocore.exceptions.ClientError: An error occurred (404) when calling the HeadObject operation: Not Found
[2023-05-09T19:16:18.544+0000] {taskinstance.py:1373} INFO - Marking task as UP_FOR_RETRY. dag_id=Summer_Warped_ETL, task_id=LoadData.LoadSongDim, execution_date=20230509T191616, start_date=20230509T191618, end_date=20230509T191618
[2023-05-09T19:16:18.559+0000] {standard_task_runner.py:109} ERROR - Failed to execute job 2985 for task LoadData.LoadSongDim (An error occurred (404) when calling the HeadObject operation: Not Found; 322)
[2023-05-09T19:16:18.595+0000] {local_task_job_runner.py:232} INFO - Task exited with return code 1
[2023-05-09T19:16:18.625+0000] {taskinstance.py:2674} INFO - 0 downstream tasks scheduled from follow-on schedule check
